<mujoco model="wheel_biped">
    <compiler angle="radian" meshdir="../meshes/" />

    <option iterations="3" ls_iterations="5" timestep="0.002" integrator="Euler">
        <flag eulerdamp="disable"/>
    </option>

    <default>
        <default class="tron">
            <geom condim="1" contype="0" conaffinity="0"/>
            <site size="0.01" rgba="1 0 0 1" group="4"/>
            <joint axis="0 0 1" damping="1.5"/>

            <default class="tron/joint">
                <default class="tron/joint/position">
                    <joint armature="0.01" frictionloss="0.3" actuatorfrcrange="-80 80"/>
                    <position kp="45" kv="1.5"/>
                </default>

                <default class="tron/joint/velocity">
                    <joint armature="0.01" frictionloss="0.01" actuatorfrcrange="-40 40"/>
                    <position kp="10" kv="0.8"/>
                </default>
            </default>

            <default class="tron/visual">
                <geom type="mesh" contype="0" conaffinity="0" density="0" group="2"/>
            </default>

            <default class="tron/collision">
                <geom group="3" rgba=".3 .3 .3 1"/>

                <default class="tron/collision/foot">
                    <geom friction="0.8 0.02 0.01" type="cylinder" size="0.127 0.005" quat="0.707107 0.707107 0 0"
                          contype="1" conaffinity="1"/>
                </default>
            </default>

            <default class="tron/site">
                <site size="0.01" rgba="1 0 0 1" group="0"/>
            </default>
        </default>
    </default>

    <visual>
        <rgba com="0.502 1.0 0 0.5" contactpoint="1.0 1.0 0.6 0.4" contactforce="0.2 0.98 0.2 0.8"/>
        <scale com="0.2" forcewidth="0.05" contactwidth="0.10" contactheight="0.04"/>
    </visual>

    <asset>
        <mesh name="base_Link" file="base_Link.STL" />
        <mesh name="abad_L_Link" file="abad_L_Link.STL" />
        <mesh name="hip_L_Link" file="hip_L_Link.STL" />
        <mesh name="knee_L_Link" file="knee_L_Link.STL" />
        <mesh name="wheel_L_Link" file="wheel_L_Link.STL" />
        <mesh name="abad_R_Link" file="abad_R_Link.STL" />
        <mesh name="hip_R_Link" file="hip_R_Link.STL" />
        <mesh name="knee_R_Link" file="knee_R_Link.STL" />
        <mesh name="wheel_R_Link" file="wheel_R_Link.STL" />
    </asset>

    <asset>
        <texture type='skybox' builtin='gradient' width='512' height='512' rgb1="1.0 1.0 1.0" rgb2="1.0 1.0 1.0"/>
        <texture name="texplane" type="2d" builtin="checker" rgb1="0.35 0.35 0.35" rgb2="0.55 0.55 0.55" width="512" height="512" mark="cross" markrgb=".8 .8 .8"/>
        <material name="matplane" reflectance="0.0" texture="texplane" texrepeat="1 1" texuniform="true"/>
    </asset>
        <option timestep="0.001"/>

    <worldbody>
        <geom name="floor" rgba="0.5 0.6 0.7 1" pos="0 0 0" size="0 0 0.25" type="plane" material="matplane" condim="3"/>
        <camera name="track" mode="trackcom" pos="0 -2.3 1.6" xyaxes="1 0 0 0 0.707 0.707"/>
        <light directional="true" diffuse=".8 .8 .8" pos="0 0 10" dir="0 0 -10"/>

        <body name="base_Link" pos="0 0 0.92">
            <inertial pos="0.0457123 0.000139854 -0.163809" quat="0.972578 -0.00615364 -0.232461 0.00398682" mass="9.595" diaginertia="0.154712 0.11093 0.0846371" />
            <joint type="free" limited="false" damping="0.0000" stiffness="0.0000" armature="0"/>
            <site name="imu" pos="0 0 0" class="tron/site"/>
            <geom class="tron/visual" rgba="0.79216 0.81961 0.93333 1" mesh="base_Link" />
            <geom name="base_collision" class="tron/collision" size="0.135 0.13 0.095" pos="0.03 0 -0.072" type="box" rgba="0 0 1 0" />

            <body name="abad_L_Link" pos="0.05556 0.105 -0.2602">
                <inertial pos="-0.06977 0.04479 0.00057" quat="0.595024 0.579772 0.394141 0.393019" mass="1.469" diaginertia="0.00252289 0.00208104 0.00139163" />
                <joint name="abad_L_Joint" pos="0 0 0" axis="1 0 0" limited="true" range="-0.38397 1.39626" />
                <geom class="tron/visual" rgba="0.79216 0.81961 0.93333 1" mesh="abad_L_Link" />
                <geom name="abad_L_collision" class="tron/collision" type="cylinder" pos="-0.08 0 0" euler="1.57 0 0" size="0.05 0.025" rgba="0 0 1 0" />

                <body name="hip_L_Link" pos="-0.077 0.0205 0">
                    <inertial pos="-0.02869 -0.0477 -0.03992" quat="0.853885 0.192797 0.226903 0.426877" mass="2.3" diaginertia="0.0233264 0.0230229 0.00277548" />
                    <joint name="hip_L_Joint" pos="0 0 0" axis="0 1 0" limited="true" range="-1.01229 1.39626" />
                    <geom class="tron/visual" rgba="1 1 1 1" mesh="hip_L_Link" />
                    <geom name="hip_L_collision" class="tron/collision" type="cylinder" pos="-0.1 -0.025 -0.14" euler="0 0.53 0" size="0.035 0.075" rgba="0 0 1 0" />

                    <body name="knee_L_Link" pos="-0.15 -0.0205 -0.25981">
                        <inertial pos="0.11913 0.01106 -0.20363" quat="0.687012 -0.159981 -0.201582 0.679548" mass="1.49" diaginertia="0.0177107 0.0171855 0.001015" />
                        <joint name="knee_L_Joint" pos="0 0 0" axis="0 -1 0" limited="true" range="-0.872665 1.36136" />
                        <geom class="tron/visual" rgba="0.79216 0.81961 0.93333 1" mesh="knee_L_Link" />
                        <geom name="knee_L_collision" class="tron/collision" type="cylinder" pos="0.078 0 -0.12" euler="0 -0.55 0" size="0.015 0.13" rgba ="0 0 1 0"/>
                        <site name="foot_L_site" pos="0.150 0 -0.2598" class="tron/site"/>

                        <body name="wheel_L_Link" pos="0.15 0.0435 -0.25981">
                            <inertial pos="3e-05 0.00807 -2e-05" quat="0.683013 0.183016 0.183017 0.683011" mass="1.08" diaginertia="0.00974272 0.00515568 0.00515344" />
                            <joint name="wheel_L_Joint" pos="0 0 0" axis="0 1 0" frictionloss="0.01" />
                            <geom class="tron/visual" rgba="0.26667 0.26667 0.26667 1" mesh="wheel_L_Link" />
                            <geom name="wheel_L_collision" pos="0.0 0.008 0.0" class="tron/collision/foot"/>
                        </body>
                    </body>
                </body>
            </body>
            <body name="abad_R_Link" pos="0.05556 -0.105 -0.2602">
                <inertial pos="-0.06977 -0.04479 0.00057" quat="0.393019 0.394141 0.579772 0.595024" mass="1.469" diaginertia="0.00252289 0.00208104 0.00139163" />
                <joint name="abad_R_Joint" pos="0 0 0" axis="1 0 0" limited="true" range="-1.39626 0.38397" />
                <geom class="tron/visual" rgba="0.79216 0.81961 0.93333 1" mesh="abad_R_Link" />
                <geom name="abad_R_collision" class="tron/collision" type="cylinder" pos="-0.08 0 0" euler="1.57 0 0" size="0.05 0.025" rgba="0 0 1 0" />

                <body name="hip_R_Link" pos="-0.077 -0.0205 0">
                    <inertial pos="-0.02869 0.0477 -0.03992" quat="0.426877 0.226903 0.192797 0.853885" mass="2.3" diaginertia="0.0233264 0.0230229 0.00277548" />
                    <joint name="hip_R_Joint" pos="0 0 0" axis="0 -1 0" limited="true" range="-1.39626 1.01229" />
                    <geom class="tron/visual" rgba="1 1 1 1" mesh="hip_R_Link" />
                    <geom name="hip_R_collision" class="tron/collision" type="cylinder" pos="-0.10 0.025 -0.14" euler="0 0.53 0" size="0.035 0.075" rgba="0 0 1 0" />

                    <body name="knee_R_Link" pos="-0.15 0.0205 -0.25981">
                        <inertial pos="0.11913 -0.01106 -0.20363" quat="0.679548 -0.201582 -0.159981 0.687012" mass="1.49" diaginertia="0.0177107 0.0171855 0.001015" />
                        <joint name="knee_R_Joint" pos="0 0 0" axis="0 1 0" limited="true" range="-1.36136 0.872665" />
                        <geom class="tron/visual" rgba="0.79216 0.81961 0.93333 1" mesh="knee_R_Link" />
                        <geom name="knee_R_collision" class="tron/collision" type="cylinder" pos="0.078 0 -0.12" euler="0 -0.55 0" size="0.015 0.13" rgba ="0 0 1 0"/>
                        <site name="foot_R_site" pos="0.150 0 -0.2598" class="tron/site"/>

                        <body name="wheel_R_Link" pos="0.15 -0.0435 -0.25981">
                            <inertial pos="3e-05 -0.00807 -2e-05" quat="0.683011 0.183017 0.183016 0.683013" mass="1.08" diaginertia="0.00974272 0.00515568 0.00515344" />
                            <joint name="wheel_R_Joint" pos="0 0 0" axis="0 1 0" frictionloss="0.01" />
                            <geom class="tron/visual" rgba="0.26667 0.26667 0.26667 1" mesh="wheel_R_Link" />
                            <geom name="wheel_R_collision" pos="0.0 -0.008 0.0" class="tron/collision/foot"/>
                        </body>
                    </body>
                </body>
            </body>
        </body>
    </worldbody>

    <actuator>
        <position class="tron/joint/position"  name="abad_L_Joint"   joint="abad_L_Joint"  />
        <position class="tron/joint/position"  name="hip_L_Joint"    joint="hip_L_Joint"   />
        <position class="tron/joint/position"  name="knee_L_Joint"   joint="knee_L_Joint"  />
        <position class="tron/joint/velocity"  name="wheel_L_Joint"  joint="wheel_L_Joint" />
        <position class="tron/joint/position"  name="abad_R_Joint"   joint="abad_R_Joint"  />
        <position class="tron/joint/position"  name="hip_R_Joint"    joint="hip_R_Joint"   />
        <position class="tron/joint/position"  name="knee_R_Joint"   joint="knee_R_Joint"  />
        <position class="tron/joint/velocity"  name="wheel_R_Joint"  joint="wheel_R_Joint" />
    </actuator>

    <sensor>
        <gyro site="imu" name="gyro"/>
        <velocimeter site="imu" name="local_linvel"/>
        <accelerometer site="imu" name="accelerometer"/>
        <framezaxis objtype="site" objname="imu" name="upvector"/>
        <framexaxis objtype="site" objname="imu" name="forwardvector"/>
        <framelinvel objtype="site" objname="imu" name="global_linvel"/>
        <frameangvel objtype="site" objname="imu" name="global_angvel"/>
        <framepos objtype="site" objname="imu" name="position"/>
        <framequat objtype="site" objname="imu" name="orientation"/>

        <framelinvel objtype="site" objname="foot_L_site" name="foot_L_site_global_linvel"/>
        <framelinvel objtype="site" objname="foot_R_site" name="foot_R_site_global_linvel"/>

        <framexaxis objtype="site" objname="foot_L_site" name="foot_L_site_upvector"/>
        <framexaxis objtype="site" objname="foot_R_site" name="foot_R_site_upvector"/>
        <framepos objtype="site" objname="foot_L_site" name="foot_L_site_pos"/>
        <framepos objtype="site" objname="foot_R_site" name="foot_R_site_pos"/>
    </sensor>

    <keyframe>
        <key name="home"
            qpos="
                0 0 1.0
                1 0 0 0
                0 0 0 0 0 0 0 0"
            ctrl="
                0 0 0 0 0 0 0 0"
        />
    </keyframe>

</mujoco>
